Workbook

Sheet Instructions
A1: Context | B1: Consider yourself founder of PoultryCare ERP as Cloud-based ERP solution specific to poultry industry, which serves for all poultry segments like layer, broiler, breeder, broiler integration, hatchery, feedmill and processing plant. As you have experience in both technology and hand-holding exposer with poultry farm owners, use your journey of this into opportunity to address poultry farmer's business needs, pain points and problems through blogs.
A2: Role | B2: You play the role of Content marketing head to position PoultryCare ERP using organic content marketing.
A3: Format
A4: Blog | B4: , description for google SEO, blog content around 5000 words with more detailed explanation having 4 to 6 sub-headings and 4 tags. Don't mention PoltryCare ERP anywhere
A5: LinkedIn | B5: LinkedIn post as conversational format as Hook/question, insightful problem statement, solution for the problem, call-to-action for engagement. Dont include section titles in the content. All within maximum 300 words. Mention PoltryCare if possible in the content, also suggest 4 hashtags addition to #poultrycare each hash tag in small character
A6: Instagram | B6: Instagram post as conversational format as Hook/question, insightful problem statement, solution for the problem, call-to-action for engagement. Dont include section titles in the content. All within maximum 300 words. Mention PoltryCare if possible in the content, also suggest 4 hashtags addition to #poultrycare each hash tag in small character
A7: Facebook | B7: Facebook post as conversational format as Hook/question, insightful problem statement, solution for the problem, call-to-action for engagement. Dont include section titles in the content. All within maximum 300 words. Mention PoltryCare if possible in the content, also suggest 4 hashtags addition to #poultrycare each hash tag in small character
A8: Twitter | B8: Twitter post as conversational format as Hook/question, insightful problem statement, solution for the problem, call-to-action for engagement. Dont include section titles in the content. All within maximum 100 words. Mention PoltryCare if possible in the content, also suggest 4 hashtags addition to #poultrycare each hash tag in small character
A9: Reals | B9: Create script for www.narakeet.com to develop reals and shots video to highlight inventory management to match Managing Contract Broiler Farming farm inventory which generates traffic for landing page matching title. Template for video script for 30 sec, should be start with hook, highlight problem statement, give solution as pointer, end with punch. Add call to action to request PoultryCare subscription for similar tips and guides
B11: Template for video script for 30 sec, should be start with hook, highlight problem statement, give solution as pointer, end with punch. Add call to action to request PoultryCare subscription for similar tips and guides

Sheet NDP
A1: Fear | B1: PainPoints | C1: Problem | D1: Needs | E1: Desire | F1: Fantasis
A2: High Mortality | B2: Feed purchase cost | C2: data manipulation | D2: Climate change introduction | E2: Sales lifting time avoid manual interruption | F2: data activity log
A3: Supply Chain | B3: Farm supervisors visit | C3: Chick placement | D3: Feed standards | E3: Low stock alerts | F3: Lifting Bluetooth integration
A4: Invesment planning | B4: Feed over stock | C4: Medications | D4: Bodyweight taking | E4: Schedule reminders | F4: feed intent based standards
A5: Birds delivery management | B5: Multiple time placement | C5: Feed quality | D5: Farm supervisor daily visit farms | E5: Farm supervisors tracking | F5: Geo mapping locations
A6: Climate chnages | B6: Recommended feed formula | C6: Recommended age feed types | D6: Sales planning | E6: Farm to foucs | F6: Wayment integrations
A7: Data security | B7: Brooding | C7: Feed transfers | D7: Birds placement planning | E7: Body Weight comparison | F7: Supply chain tracking
B8: Farmers birds stock Management | C8: Farmers training | D8: Farmer checklist instructions | E8: Performance comparesion to plcement | F8: Maturity birds
B9: Feed nutrients | C9: Birds shortages | D9: Broiler integration | E9: Growing charge Repat Birds shoratage | F9: unpaid purchase
B10: Feed forecast | C10: Unvisited farms | D10: debugging | E10: Suppliers due amount | F10: unreceived invoices
B11: Medication schedule | C11: Mean age | D11: maturity date | E11: Customers due amount | F11: Growing Charge scheme
C12: Fcr high | D12: Farm to Focus | E12: Shed ready checklist | F12: sequence approval
C13: Body weight low | D13: Unvisited farms | E13: High mean age | F13: Fcr incentives
C14: Biosecurity | D14: Farmer performances | E14: Birds paced sizing | F14: Employee Allowance clainming
C15: High feed intake farms | D15: Farm capacity take intent birds | E15: Capacity to blow bird's placement | F15: Estimation chicks
C16: High birds placement | D16: Feed intent | E16: High mortality alert | F16: Perbird intake
C17: Employee consequences | D17: Contract farmars | E17: Temperature Monitor | F17: Recommed feed per age
C18: inter farm feed transfer | D18: Farmers education | E18: Water Intake | F18: Production cost
D19: Line run | E19: Folck tracking | F19: Cull brids
D20: Farm visit tracking | E20: EEF | F20: Rate Materix
D21: Optimum placement gap dates | E21: Farmer Grade | F21: Maintenance
D22: Breed standars | E22: Line accountability
D23: Observations
D24: Farmer Journal
D25: Branch tracking
D26: Livability
D27: Depleation

Sheet Keywords
A1: Farm | B1: Categories | C1: NDP | D1: 1st | E1: 2nd | F1: 3rd
A2: CBF Farm | B2: Fear | C2: High Mortality | D2: CBF Disease Management | E2: Act as a founder of PoultryCare ERP as Cloud-based ERP solution specific to poultry industry, which serves for all poultry segments like layer, broiler, breeder, broiler integration, hatchery, feedmill and processing plant. As you have experience in both technology and hand-holding exposer with poultry farm owners, use your journey of this into opportunity to address poultry farmer's business needs, pain points and problems through blogs. You play the role of Content marketing head to position PoultryCare ERP using organic content marketing. You Are planning to run a blog for Contract broiler farming for 50 days and educate a poultry farmers, to resolving their fear like ( High Mortality, Supply Chain(feed), Invesment planning, Birds delivery management, Climate changes, Data security ) , Pain points like ( Feed purchase cost, Farm supervisors visit, Feed over stock, Multiple time placement, Recommended feed formula, Brooding, Farmers birds stock Management, Feed nutrients, Feed forecast, Medication schedule ), and their facing a problems like (data manipulation, Chick placement, Medications, Feed quality, Recommended age feed types, Feed transfers, Farmers training, Birds shortages, Unvisited farms, Mean age , Fcr high, Body weight low, Biosecurity, High feed intake farms, High birds placement, Employee consequences, inter farm feed transfer ), And their needs to develope their farm are ( Climate change introduction, Feed standards, Bodyweight taking, Farm supervisor daily visit farms, Sales planning, Birds placement planning, Farmer checklist instructions, Broiler integration, debugging, maturity date, Farm to Focus, Unvisited farms, Farmer performances, Farm capacity take intent birds, Feed intent , Contract farmars, Farmers education, Line run, Farm visit tracking, Optimum placement gap dates, Breed standars, Observations, Farmer Journal, Branch trackin, , Livability, Depleation ) and how to desire their needs by ( Sales lifting time avoid manual interruption, Low stock alerts, Schedule reminders, Farm supervisors tracking, Farm to foucs, Body Weight comparison, Performance comparesion to plcement, Growing charge Repat Birds shoratage, Suppliers due amount, Customers due amount, Shed ready checklist, High mean age, Birds paced sizing, Capacity to blow bird's placement, High mortality alert, Temperature Monitor,Water Intake, Folck tracking, EEF, Farmer Grade, Line accountability )and how its helps to fullfill their fantasis ( Schedule based production, Indent based projection, Projection based sotck comparesion, Formula cost analysics, Yeild comparesion, Cost per kg analysics, Autom remind stock less, Lab test report ananalysics, Purchase flow tracking, inventory to production comparesion, Current stock based closing stock value, Production loss, Order managment, Moisture loss, Real time cost tracking, Order based feed delivery, Materil cost ananysics, Low stock notification, Expect feed output to actual out put comparesion, Feed production compase standard nutrients, Stage wise feed scheduling, Age wise feed recommded quanity, Cost comparesion production to production, Feed supply chain management ) give heading for 50 day to run a blog for educating poultry farmers with poultry farmers understanding tone to create more engagement Don't mention PoltryCare ERP anywhere to create more engagement.
A3: CBF Farm | B3: Fear | C3: Supply Chain(feed) | D3: inventory management
A4: CBF Farm | B4: Fear | C4: Invesment planning | D4: Farmer score based invesment
A5: CBF Farm | B5: Fear | C5: Birds delivery management | D5: Birds lifting
A6: CBF Farm | B6: Fear | C6: Climate changes | D6: Weather preparedness
A7: CBF Farm | B7: Fear | C7: Data security | D7: bio-security management
A8: CBF Farm | B8: PainPoints | C8: Feed purchase cost | D8: Feed cost analtics
A9: CBF Farm | B9: PainPoints | C9: Farm supervisors visit | D9: Regular monitoring
A10: CBF Farm | B10: PainPoints | C10: Feed over stock | D10: Feed stock management
A11: CBF Farm | B11: PainPoints | C11: Multiple time placement | D11: Birds age variation
A12: CBF Farm | B12: PainPoints | C12: Recommended feed formula | D12: Feed formula counselling
A13: CBF Farm | B13: PainPoints | C13: Brooding | D13: Brooding statergies,
A14: CBF Farm | B14: PainPoints | C14: Farmers birds stock Management | D14: Birds count tracking
... A35: CBF Farm | B35: Needs | C35: Climate change introduction | D35: Weather Guidence
A36: CBF Farm | B36: Needs | C36: Feed standards
A37: CBF Farm | B37: Needs | C37: Bodyweight taking
A38: CBF Farm | B38: Needs | C38: Farm supervisor daily visit farms
A39: CBF Farm | B39: Needs | C39: Sales planning
A40: CBF Farm | B40: Needs | C40: Birds placement planning
A41: CBF Farm | B41: Needs | C41: Farmer checklist instructions
A42: CBF Farm | B42: Needs | C42: Broiler integration
A43: CBF Farm | B43: Needs | C43: debugging
A44: CBF Farm | B44: Needs | C44: maturity date
A45: CBF Farm | B45: Needs | C45: Farm to Focus
A46: CBF Farm | B46: Needs | C46: Unvisited farms
A47: CBF Farm | B47: Needs | C47: Farmer performances
... A101: CBF Farm | B101: Fantasis | C101: Maintenance
A102: CBF Farm
A103: CBF Farm
A104: CBF Farm
A105: CBF Farm
A106: CBF Farm
A107: CBF Farm
A108: CBF Farm
A109: CBF Farm
A110: CBF Farm
A111: CBF Farm

Sheet Calender
A1: S.No | B1: Content | C1: Prompt | D1: Date | E1: Title | F1: Link | G1: medium website
A2: 1 | B2: How to Overcome High Mortality Rates in Contract Broiler Farming | C2: =CONCATENATE("Act as a founder of PoultryCare ERP as Cloud-based ERP solution specific to poultry industry, which serves for all poultry segments like layer, broiler, breeder, broiler integration, hatchery, feedmill and processing plant. As you have experience in both "&"technology and hand-holding exposer with poultry farm owners, use your journey of this into opportunity to address poultry farmer's business needs, pain points and problems through blogs. You play the role of Content marketing head to position PoultryCare"&" ERP using organic content marketing. You Are planning to run a blog for Feed Mill management and educate a poultry farmers, to resolving their", B2," give heading for run a blog for educating poultry farmers with their tone to create more engagement Write a title with SEO keywords to hook visitors to continue reading, description for google SEO,Blogs convert traffic into leads. Blogs go above and beyo"&"nd product descriptions. blog content around 3000 words with more detailed explanation having 4 to 6 sub-headings and 4 tags. give the 3 keywords, Don't mention PoltryCare ERP anywhere Content should be Farmel understanding tone to create more engagement "&"and analysis with google SEO.") -> Act as a founder of PoultryCare ERP as Cloud-based ERP solution specific to poultry industry, which serves for all poultry segments like layer, broiler, breeder, broiler integration, hatchery, feedmill and processing plant. As you have experience in both technology and hand-holding exposer with poultry farm owners, use your journey of this into opportunity to address poultry farmer's business needs, pain points and problems through blogs. You play the role of Content marketing head to position PoultryCare ERP using organic content marketing. You Are planning to run a blog for Feed Mill management and educate a poultry farmers, to resolving theirHow to Overcome High Mortality Rates in Contract Broiler Farming give heading for run a blog for educating poultry farmers with their tone to create more engagement Write a title with SEO keywords to hook visitors to continue reading, description for google SEO,Blogs convert traffic into leads. Blogs go above and beyond product descriptions. blog content around 3000 words with more detailed explanation having 4 to 6 sub-headings and 4 tags. give the 3 keywords, Don't mention PoltryCare ERP anywhere Content should be Farmel understanding tone to create more engagement and analysis with google SEO. | D2: 45540 | E2: Proven Techniques to Minimize Mortality Rates in Contract Broiler Farming | F2: https://www.poultry.care/blog/proven-techniques-to-minimize-mortality-rates-in-contract-broiler-farming
A3: 2 | B3: Feed Supply Chain Challenges in Contract Broiler Farming and How to Tackle Them Effectively | C3: =CONCATENATE("Act as a founder of PoultryCare ERP as Cloud-based ERP solution specific to poultry industry, which serves for all poultry segments like layer, broiler, breeder, broiler integration, hatchery, feedmill and processing plant. As you have experience in both "&"technology and hand-holding exposer with poultry farm owners, use your journey of this into opportunity to address poultry farmer's business needs, pain points and problems through blogs. You play the role of Content marketing head to position PoultryCare"&" ERP using organic content marketing. You Are planning to run a blog for Feed Mill management and educate a poultry farmers, to resolving their", B3," give heading for run a blog for educating poultry farmers with their tone to create more engagement Write a title with SEO keywords to hook visitors to continue reading, description for google SEO,Blogs convert traffic into leads. Blogs go above and beyo"&"nd product descriptions. blog content around 3000 words with more detailed explanation having 4 to 6 sub-headings and 4 tags. give the 3 keywords, Don't mention PoltryCare ERP anywhere Content should be Farmel understanding tone to create more engagement "&"and analysis with google SEO.") -> Act as a founder of PoultryCare ERP as Cloud-based ERP solution specific to poultry industry, which serves for all poultry segments like layer, broiler, breeder, broiler integration, hatchery, feedmill and processing plant. As you have experience in both technology and hand-holding exposer with poultry farm owners, use your journey of this into opportunity to address poultry farmer's business needs, pain points and problems through blogs. You play the role of Content marketing head to position PoultryCare ERP using organic content marketing. You Are planning to run a blog for Feed Mill management and educate a poultry farmers, to resolving theirFeed Supply Chain Challenges in Contract Broiler Farming and How to Tackle Them Effectively give heading for run a blog for educating poultry farmers with their tone to create more engagement Write a title with SEO keywords to hook visitors to continue reading, description for google SEO,Blogs convert traffic into leads. Blogs go above and beyond product descriptions. blog content around 3000 words with more detailed explanation having 4 to 6 sub-headings and 4 tags. give the 3 keywords, Don't mention PoltryCare ERP anywhere Content should be Farmel understanding tone to create more engagement and analysis with google SEO. | D3: 45542 | E3: Navigating Feed Supply Chain Challenges in Contract Broiler Farming | F3: https://www.poultry.care/blog/navigating-feed-supply-chain-challenges-in-contract-broiler-farming
A4: 3 | B4: Investment Planning for Contract Broiler Farming: Key Insights for Success | C4: =CONCATENATE("Act as a founder of PoultryCare ERP as Cloud-based ERP solution specific to poultry industry, which serves for all poultry segments like layer, broiler, breeder, broiler integration, hatchery, feedmill and processing plant. As you have experience in both "&"technology and hand-holding exposer with poultry farm owners, use your journey of this into opportunity to address poultry farmer's business needs, pain points and problems through blogs. You play the role of Content marketing head to position PoultryCare"&" ERP using organic content marketing. You Are planning to run a blog for Feed Mill management and educate a poultry farmers, to resolving their", B4," give heading for run a blog for educating poultry farmers with their tone to create more engagement Write a title with SEO keywords to hook visitors to continue reading, description for google SEO,Blogs convert traffic into leads. Blogs go above and beyo"&"nd product descriptions. blog content around 3000 words with more detailed explanation having 4 to 6 sub-headings and 4 tags. give the 3 keywords, Don't mention PoltryCare ERP anywhere Content should be Farmel understanding tone to create more engagement "&"and analysis with google SEO.") -> Act as a founder of PoultryCare ERP as Cloud-based ERP solution specific to poultry industry, which serves for all poultry segments like layer, broiler, breeder, broiler integration, hatchery, feedmill and processing plant. As you have experience in both technology and hand-holding exposer with poultry farm owners, use your journey of this into opportunity to address poultry farmer's business needs, pain points and problems through blogs. You play the role of Content marketing head to position PoultryCare ERP using organic content marketing. You Are planning to run a blog for Feed Mill management and educate a poultry farmers, to resolving theirInvestment Planning for Contract Broiler Farming: Key Insights for Success give heading for run a blog for educating poultry farmers with their tone to create more engagement Write a title with SEO keywords to hook visitors to continue reading, description for google SEO,Blogs convert traffic into leads. Blogs go above and beyond product descriptions. blog content around 3000 words with more detailed explanation having 4 to 6 sub-headings and 4 tags. give the 3 keywords, Don't mention PoltryCare ERP anywhere Content should be Farmel understanding tone to create more engagement and analysis with google SEO. | D4: 45544 | E4: Mastering Investment Planning for Contract Broiler Farming | F4: https://www.poultry.care/blog/mastering-investment-planning-for-contract-broiler-farming
A5: 4 | B5: Optimizing Birds Delivery Management in Contract Broiler Farming for Consistent Results | C5: =CONCATENATE("Act as a founder of PoultryCare ERP as Cloud-based ERP solution specific to poultry industry, which serves for all poultry segments like layer, broiler, breeder, broiler integration, hatchery, feedmill and processing plant. As you have experience in both "&"technology and hand-holding exposer with poultry farm owners, use your journey of this into opportunity to address poultry farmer's business needs, pain points and problems through blogs. You play the role of Content marketing head to position PoultryCare"&" ERP using organic content marketing. You Are planning to run a blog for Feed Mill management and educate a poultry farmers, to resolving their", B5," give heading for run a blog for educating poultry farmers with their tone to create more engagement Write a title with SEO keywords to hook visitors to continue reading, description for google SEO,Blogs convert traffic into leads. Blogs go above and beyo"&"nd product descriptions. blog content around 3000 words with more detailed explanation having 4 to 6 sub-headings and 4 tags. give the 3 keywords, Don't mention PoltryCare ERP anywhere Content should be Farmel understanding tone to create more engagement "&"and analysis with google SEO.") -> Act as a founder of PoultryCare ERP as Cloud-based ERP solution specific to poultry industry, which serves for all poultry segments like layer, broiler, breeder, broiler integration, hatchery, feedmill and processing plant. As you have experience in both technology and hand-holding exposer with poultry farm owners, use your journey of this into opportunity to address poultry farmer's business needs, pain points and problems through blogs. You play the role of Content marketing head to position PoultryCare ERP using organic content marketing. You Are planning to run a blog for Feed Mill management and educate a poultry farmers, to resolving theirOptimizing Birds Delivery Management in Contract Broiler Farming for Consistent Results give heading for run a blog for educating poultry farmers with their tone to create more engagement Write a title with SEO keywords to hook visitors to continue reading, description for google SEO,Blogs convert traffic into leads. Blogs go above and beyond product descriptions. blog content around 3000 words with more detailed explanation having 4 to 6 sub-headings and 4 tags. give the 3 keywords, Don't mention PoltryCare ERP anywhere Content should be Farmel understanding tone to create more engagement and analysis with google SEO. | D5: 45546 | E5: Optimizing Bird Delivery Management in Contract Broiler Farming for Consistent Results | F5: https://www.poultry.care/blog/optimizing-bird-delivery-management-in-contract-broiler-farming-for-consistent-results
A6: 5 | B6: Preparing Your Contract Broiler Farming Operation for Climate Change | C6: =CONCATENATE("Act as a founder of PoultryCare ERP as Cloud-based ERP solution specific to poultry industry, which serves for all poultry segments like layer, broiler, breeder, broiler integration, hatchery, feedmill and processing plant. As you have experience in both "&"technology and hand-holding exposer with poultry farm owners, use your journey of this into opportunity to address poultry farmer's business needs, pain points and problems through blogs. You play the role of Content marketing head to position PoultryCare"&" ERP using organic content marketing. You Are planning to run a blog for Feed Mill management and educate a poultry farmers, to resolving their", B6," give heading for run a blog for educating poultry farmers with their tone to create more engagement Write a title with SEO keywords to hook visitors to continue reading, description for google SEO,Blogs convert traffic into leads. Blogs go above and beyo"&"nd product descriptions. blog content around 3000 words with more detailed explanation having 4 to 6 sub-headings and 4 tags. give the 3 keywords, Don't mention PoltryCare ERP anywhere Content should be Farmel understanding tone to create more engagement "&"and analysis with google SEO.") -> Act as a founder of PoultryCare ERP as Cloud-based ERP solution specific to poultry industry, which serves for all poultry segments like layer, broiler, breeder, broiler integration, hatchery, feedmill and processing plant. As you have experience in both technology and hand-holding exposer with poultry farm owners, use your journey of this into opportunity to address poultry farmer's business needs, pain points and problems through blogs. You play the role of Content marketing head to position PoultryCare ERP using organic content marketing. You Are planning to run a blog for Feed Mill management and educate a poultry farmers, to resolving theirPreparing Your Contract Broiler Farming Operation for Climate Change give heading for run a blog for educating poultry farmers with their tone to create more engagement Write a title with SEO keywords to hook visitors to continue reading, description for google SEO,Blogs convert traffic into leads. Blogs go above and beyond product descriptions. blog content around 3000 words with more detailed explanation having 4 to 6 sub-headings and 4 tags. give the 3 keywords, Don't mention PoltryCare ERP anywhere Content should be Farmel understanding tone to create more engagement and analysis with google SEO. | D6: 45548 | E6: Preparing Your Contract Broiler Farming Operation for Climate Change | F6: https://www.poultry.care/blog/preparing-your-contract-broiler-farming-operation-for-climate-change
A7: 6 | B7: The Importance of Data Security in Contract Broiler Farming | C7: =CONCATENATE("Act as a founder of PoultryCare ERP as Cloud-based ERP solution specific to poultry industry, which serves for all poultry segments like layer, broiler, breeder, broiler integration, hatchery, feedmill and processing plant. As you have experience in both "&"technology and hand-holding exposer with poultry farm owners, use your journey of this into opportunity to address poultry farmer's business needs, pain points and problems through blogs. You play the role of Content marketing head to position PoultryCare"&" ERP using organic content marketing. You Are planning to run a blog for Feed Mill management and educate a poultry farmers, to resolving their", B7," give heading for run a blog for educating poultry farmers with their tone to create more engagement Write a title with SEO keywords to hook visitors to continue reading, description for google SEO,Blogs convert traffic into leads. Blogs go above and beyo"&"nd product descriptions. blog content around 3000 words with more detailed explanation having 4 to 6 sub-headings and 4 tags. give the 3 keywords, Don't mention PoltryCare ERP anywhere Content should be Farmel understanding tone to create more engagement "&"and analysis with google SEO.") -> Act as a founder of PoultryCare ERP as Cloud-based ERP solution specific to poultry industry, which serves for all poultry segments like layer, broiler, breeder, broiler integration, hatchery, feedmill and processing plant. As you have experience in both technology and hand-holding exposer with poultry farm owners, use your journey of this into opportunity to address poultry farmer's business needs, pain points and problems through blogs. You play the role of Content marketing head to position PoultryCare ERP using organic content marketing. You Are planning to run a blog for Feed Mill management and educate a poultry farmers, to resolving theirThe Importance of Data Security in Contract Broiler Farming give heading for run a blog for educating poultry farmers with their tone to create more engagement Write a title with SEO keywords to hook visitors to continue reading, description for google SEO,Blogs convert traffic into leads. Blogs go above and beyond product descriptions. blog content around 3000 words with more detailed explanation having 4 to 6 sub-headings and 4 tags. give the 3 keywords, Don't mention PoltryCare ERP anywhere Content should be Farmel understanding tone to create more engagement and analysis with google SEO. | D7: 45550 | E7: Why Data Security is Essential for Your Feed Mill in Poultry Farming | F7: https://www.poultry.care/blog/why-data-security-is-essential-for-your-feed-mill-in-poultry-farming
A8: 7 | B8: Managing Feed Purchase Costs to Maximize Profitability in Contract Broiler Farming | C8: =CONCATENATE("Act as a founder of PoultryCare ERP as Cloud-based ERP solution specific to poultry industry, which serves for all poultry segments like layer, broiler, breeder, broiler integration, hatchery, feedmill and processing plant. As you have experience in both "&"technology and hand-holding exposer with poultry farm owners, use your journey of this into opportunity to address poultry farmer's business needs, pain points and problems through blogs. You play the role of Content marketing head to position PoultryCare"&" ERP using organic content marketing. You Are planning to run a blog for Feed Mill management and educate a poultry farmers, to resolving their", B8," give heading for run a blog for educating poultry farmers with their tone to create more engagement Write a title with SEO keywords to hook visitors to continue reading, description for google SEO,Blogs convert traffic into leads. Blogs go above and beyo"&"nd product descriptions. blog content around 3000 words with more detailed explanation having 4 to 6 sub-headings and 4 tags. give the 3 keywords, Don't mention PoltryCare ERP anywhere Content should be Farmel understanding tone to create more engagement "&"and analysis with google SEO.") -> Act as a founder of PoultryCare ERP as Cloud-based ERP solution specific to poultry industry, which serves for all poultry segments like layer, broiler, breeder, broiler integration, hatchery, feedmill and processing plant. As you have experience in both technology and hand-holding exposer with poultry farm owners, use your journey of this into opportunity to address poultry farmer's business needs, pain points and problems through blogs. You play the role of Content marketing head to position PoultryCare ERP using organic content marketing. You Are planning to run a blog for Feed Mill management and educate a poultry farmers, to resolving theirManaging Feed Purchase Costs to Maximize Profitability in Contract Broiler Farming give heading for run a blog for educating poultry farmers with their tone to create more engagement Write a title with SEO keywords to hook visitors to continue reading, description for google SEO,Blogs convert traffic into leads. Blogs go above and beyond product descriptions. blog content around 3000 words with more detailed explanation having 4 to 6 sub-headings and 4 tags. give the 3 keywords, Don't mention PoltryCare ERP anywhere Content should be Farmel understanding tone to create more engagement and analysis with google SEO. | D8: 45552 | E8: How to Cut Feed Costs and Boost Profits in Broiler Farming | F8: https://www.poultry.care/blog/how-to-cut-feed-costs-and-boost-profits-in-broiler-farming
A9: 8 | B9: The Value of Regular Farm Supervisor Visits for Contract Broiler Farming | C9: =CONCATENATE("Act as a founder of PoultryCare ERP as Cloud-based ERP solution specific to poultry industry, which serves for all poultry segments like layer, broiler, breeder, broiler integration, hatchery, feedmill and processing plant. As you have experience in both "&"technology and hand-holding exposer with poultry farm owners, use your journey of this into opportunity to address poultry farmer's business needs, pain points and problems through blogs. You play the role of Content marketing head to position PoultryCare"&" ERP using organic content marketing. You Are planning to run a blog for Feed Mill management and educate a poultry farmers, to resolving their", B9," give heading for run a blog for educating poultry farmers with their tone to create more engagement Write a title with SEO keywords to hook visitors to continue reading, description for google SEO,Blogs convert traffic into leads. Blogs go above and beyo"&"nd product descriptions. blog content around 3000 words with more detailed explanation having 4 to 6 sub-headings and 4 tags. give the 3 keywords, Don't mention PoltryCare ERP anywhere Content should be Farmel understanding tone to create more engagement "&"and analysis with google SEO.") -> Act as a founder of PoultryCare ERP as Cloud-based ERP solution specific to poultry industry, which serves for all poultry segments like layer, broiler, breeder, broiler integration, hatchery, feedmill and processing plant. As you have experience in both technology and hand-holding exposer with poultry farm owners, use your journey of this into opportunity to address poultry farmer's business needs, pain points and problems through blogs. You play the role of Content marketing head to position PoultryCare ERP using organic content marketing. You Are planning to run a blog for Feed Mill management and educate a poultry farmers, to resolving theirThe Value of Regular Farm Supervisor Visits for Contract Broiler Farming give heading for run a blog for educating poultry farmers with their tone to create more engagement Write a title with SEO keywords to hook visitors to continue reading, description for google SEO,Blogs convert traffic into leads. Blogs go above and beyond product descriptions. blog content around 3000 words with more detailed explanation having 4 to 6 sub-headings and 4 tags. give the 3 keywords, Don't mention PoltryCare ERP anywhere Content should be Farmel understanding tone to create more engagement and analysis with google SEO. | D9: 45554 | E9: Why Regular Farm Supervisor Visits Are Key to Success in Contract Broiler Farming | F9: https://www.poultry.care/blog/why-regular-farm-supervisor-visits-are-key-to-success-in-contract-broiler-farming
A10: 9 | B10: How to Prevent Overstocking Feed on Your Contract Broiler Farm | C10: =CONCATENATE("Act as a founder of PoultryCare ERP as Cloud-based ERP solution specific to poultry industry, which serves for all poultry segments like layer, broiler, breeder, broiler integration, hatchery, feedmill and processing plant. As you have experience in both "&"technology and hand-holding exposer with poultry farm owners, use your journey of this into opportunity to address poultry farmer's business needs, pain points and problems through blogs. You play the role of Content marketing head to position PoultryCare"&" ERP using organic content marketing. You Are planning to run a blog for Feed Mill management and educate a poultry farmers, to resolving their", B10," give heading for run a blog for educating poultry farmers with their tone to create more engagement Write a title with SEO keywords to hook visitors to continue reading, description for google SEO,Blogs convert traffic into leads. Blogs go above and beyo"&"nd product descriptions. blog content around 3000 words with more detailed explanation having 4 to 6 sub-headings and 4 tags. give the 3 keywords, Don't mention PoltryCare ERP anywhere Content should be Farmel understanding tone to create more engagement "&"and analysis with google SEO.") -> Act as a founder of PoultryCare ERP as Cloud-based ERP solution specific to poultry industry, which serves for all poultry segments like layer, broiler, breeder, broiler integration, hatchery, feedmill and processing plant. As you have experience in both technology and hand-holding exposer with poultry farm owners, use your journey of this into opportunity to address poultry farmer's business needs, pain points and problems through blogs. You play the role of Content marketing head to position PoultryCare ERP using organic content marketing. You Are planning to run a blog for Feed Mill management and educate a poultry farmers, to resolving theirHow to Prevent Overstocking Feed on Your Contract Broiler Farm give heading for run a blog for educating poultry farmers with their tone to create more engagement Write a title with SEO keywords to hook visitors to continue reading, description for google SEO,Blogs convert traffic into leads. Blogs go above and beyond product descriptions. blog content around 3000 words with more detailed explanation having 4 to 6 sub-headings and 4 tags. give the 3 keywords, Don't mention PoltryCare ERP anywhere Content should be Farmel understanding tone to create more engagement and analysis with google SEO. | D10: 45556 | E10: Effective Strategies to Prevent Overstocking Feed on Your Contract Broiler Farm | F10: https://www.poultry.care/blog/effective-strategies-to-prevent-overstocking-feed-on-your-contract-broiler-farm
A11: 10 | B11: Managing Multiple Chick Placements with Efficiency in Contract Broiler Farming | C11: =CONCATENATE("Act as a founder of PoultryCare ERP as Cloud-based ERP solution specific to poultry industry, which serves for all poultry segments like layer, broiler, breeder, broiler integration, hatchery, feedmill and processing plant. As you have experience in both "&"technology and hand-holding exposer with poultry farm owners, use your journey of this into opportunity to address poultry farmer's business needs, pain points and problems through blogs. You play the role of Content marketing head to position PoultryCare"&" ERP using organic content marketing. You Are planning to run a blog for Feed Mill management and educate a poultry farmers, to resolving their", B11," give heading for run a blog for educating poultry farmers with their tone to create more engagement Write a title with SEO keywords to hook visitors to continue reading, description for google SEO,Blogs convert traffic into leads. Blogs go above and beyo"&"nd product descriptions. blog content around 3000 words with more detailed explanation having 4 to 6 sub-headings and 4 tags. give the 3 keywords, Don't mention PoltryCare ERP anywhere Content should be Farmel understanding tone to create more engagement "&"and analysis with google SEO.") -> Act as a founder of PoultryCare ERP as Cloud-based ERP solution specific to poultry industry, which serves for all poultry segments like layer, broiler, breeder, broiler integration, hatchery, feedmill and processing plant. As you have experience in both technology and hand-holding exposer with poultry farm owners, use your journey of this into opportunity to address poultry farmer's business needs, pain points and problems through blogs. You play the role of Content marketing head to position PoultryCare ERP using organic content marketing. You Are planning to run a blog for Feed Mill management and educate a poultry farmers, to resolving theirManaging Multiple Chick Placements with Efficiency in Contract Broiler Farming give heading for run a blog for educating poultry farmers with their tone to create more engagement Write a title with SEO keywords to hook visitors to continue reading, description for google SEO,Blogs convert traffic into leads. Blogs go above and beyond product descriptions. blog content around 3000 words with more detailed explanation having 4 to 6 sub-headings and 4 tags. give the 3 keywords, Don't mention PoltryCare ERP anywhere Content should be Farmel understanding tone to create more engagement and analysis with google SEO. | D11: 45558 | E11: How to Efficiently Manage Multiple Chick Placements in Contract Broiler Farming | F11: https://www.poultry.care/blog/how-to-efficiently-manage-multiple-chick-placements-in-contract-broiler-farming
A12: 11 | B12: Understanding and Implementing the Recommended Feed Formula in Contract Broiler Farming | C12: =CONCATENATE("Act as a founder of PoultryCare ERP as Cloud-based ERP solution specific to poultry industry, which serves for all poultry segments like layer, broiler, breeder, broiler integration, hatchery, feedmill and processing plant. As you have experience in both "&"technology and hand-holding exposer with poultry farm owners, use your journey of this into opportunity to address poultry farmer's business needs, pain points and problems through blogs. You play the role of Content marketing head to position PoultryCare"&" ERP using organic content marketing. You Are planning to run a blog for Feed Mill management and educate a poultry farmers, to resolving their", B12," give heading for run a blog for educating poultry farmers with their tone to create more engagement Write a title with SEO keywords to hook visitors to continue reading, description for google SEO,Blogs convert traffic into leads. Blogs go above and beyo"&"nd product descriptions. blog content around 3000 words with more detailed explanation having 4 to 6 sub-headings and 4 tags. give the 3 keywords, Don't mention PoltryCare ERP anywhere Content should be Farmel understanding tone to create more engagement "&"and analysis with google SEO.") -> Act as a founder of PoultryCare ERP as Cloud-based ERP solution specific to poultry industry, which serves for all poultry segments like layer, broiler, breeder, broiler integration, hatchery, feedmill and processing plant. As you have experience in both technology and hand-holding exposer with poultry farm owners, use your journey of this into opportunity to address poultry farmer's business needs, pain points and problems through blogs. You play the role of Content marketing head to position PoultryCare ERP using organic content marketing. You Are planning to run a blog for Feed Mill management and educate a poultry farmers, to resolving theirUnderstanding and Implementing the Recommended Feed Formula in Contract Broiler Farming give heading for run a blog for educating poultry farmers with their tone to create more engagement Write a title with SEO keywords to hook visitors to continue reading, description for google SEO,Blogs convert traffic into leads. Blogs go above and beyond product descriptions. blog content around 3000 words with more detailed explanation having 4 to 6 sub-headings and 4 tags. give the 3 keywords, Don't mention PoltryCare ERP anywhere Content should be Farmel understanding tone to create more engagement and analysis with google SEO. | D12: 45560 | E12: Mastering the Use of Recommended Feed Formulas in Contract Broiler Farming | F12: https://www.poultry.care/blog/mastering-the-use-of-recommended-feed-formulas-in-contract-broiler-farming
A13: 12 | B13: Brooding Best Practices to Ensure Healthy Chick Development in Contract Broiler Farming | C13: =CONCATENATE("Act as a founder of PoultryCare ERP as Cloud-based ERP solution specific to poultry industry, which serves for all poultry segments like layer, broiler, breeder, broiler integration, hatchery, feedmill and processing plant. As you have experience in both "&"technology and hand-holding exposer with poultry farm owners, use your journey of this into opportunity to address poultry farmer's business needs, pain points and problems through blogs. You play the role of Content marketing head to position PoultryCare"&" ERP using organic content marketing. You Are planning to run a blog for Feed Mill management and educate a poultry farmers, to resolving their", B13," give heading for run a blog for educating poultry farmers with their tone to create more engagement Write a title with SEO keywords to hook visitors to continue reading, description for google SEO,Blogs convert traffic into leads. Blogs go above and beyo"&"nd product descriptions. blog content around 3000 words with more detailed explanation having 4 to 6 sub-headings and 4 tags. give the 3 keywords, Don't mention PoltryCare ERP anywhere Content should be Farmel understanding tone to create more engagement "&"and analysis with google SEO.") -> Act as a founder of PoultryCare ERP as Cloud-based ERP solution specific to poultry industry, which serves for all poultry segments like layer, broiler, breeder, broiler integration, hatchery, feedmill and processing plant. As you have experience in both technology and hand-holding exposer with poultry farm owners, use your journey of this into opportunity to address poultry farmer's business needs, pain points and problems through blogs. You play the role of Content marketing head to position PoultryCare ERP using organic content marketing. You Are planning to run a blog for Feed Mill management and educate a poultry farmers, to resolving theirBrooding Best Practices to Ensure Healthy Chick Development in Contract Broiler Farming give heading for run a blog for educating poultry farmers with their tone to create more engagement Write a title with SEO keywords to hook visitors to continue reading, description for google SEO,Blogs convert traffic into leads. Blogs go above and beyond product descriptions. blog content around 3000 words with more detailed explanation having 4 to 6 sub-headings and 4 tags. give the 3 keywords, Don't mention PoltryCare ERP anywhere Content should be Farmel understanding tone to create more engagement and analysis with google SEO. | D13: 45562 | E13: Brooding Techniques Every Poultry Farmer Should Know for Strong and Healthy Chicks | F13: https://www.poultry.care/blog/brooding-techniques-every-poultry-farmer-should-know-for-strong-and-healthy-chicks
A14: 13 | B14: Effectively Managing Bird Stock in Contract Broiler Farming to Avoid Shortages | C14: =CONCATENATE("Act as a founder of PoultryCare ERP as Cloud-based ERP solution specific to poultry industry, which serves for all poultry segments like layer, broiler, breeder, broiler integration, hatchery, feedmill and processing plant. As you have experience in both "&"technology and hand-holding exposer with poultry farm owners, use your journey of this into opportunity to address poultry farmer's business needs, pain points and problems through blogs. You play the role of Content marketing head to position PoultryCare"&" ERP using organic content marketing. You Are planning to run a blog for Feed Mill management and educate a poultry farmers, to resolving their", B14," give heading for run a blog for educating poultry farmers with their tone to create more engagement Write a title with SEO keywords to hook visitors to continue reading, description for google SEO,Blogs convert traffic into leads. Blogs go above and beyo"&"nd product descriptions. blog content around 1000 words with more detailed explanation having 4 to 6 sub-headings and 4 tags. give the 3 keywords, Don't mention PoltryCare ERP anywhere Content should be Farmel understanding tone to create more engagement "&"and analysis with google SEO.") -> Act as a founder of PoultryCare ERP as Cloud-based ERP solution specific to poultry industry, which serves for all poultry segments like layer, broiler, breeder, broiler integration, hatchery, feedmill and processing plant. As you have experience in both technology and hand-holding exposer with poultry farm owners, use your journey of this into opportunity to address poultry farmer's business needs, pain points and problems through blogs. You play the role of Content marketing head to position PoultryCare ERP using organic content marketing. You Are planning to run a blog for Feed Mill management and educate a poultry farmers, to resolving theirEffectively Managing Bird Stock in Contract Broiler Farming to Avoid Shortages give heading for run a blog for educating poultry farmers with their tone to create more engagement Write a title with SEO keywords to hook visitors to continue reading, description for google SEO,Blogs convert traffic into leads. Blogs go above and beyond product descriptions. blog content around 1000 words with more detailed explanation having 4 to 6 sub-headings and 4 tags. give the 3 keywords, Don't mention PoltryCare ERP anywhere Content should be Farmel understanding tone to create more engagement and analysis with google SEO. | D14: 45564 | E14: Smart Bird Stock Management for Contract Broiler Farmers to Avoid Supply Gaps | F14: https://www.poultry.care/blog/smart-bird-stock-management-for-contract-broiler-farmers-to-avoid-supply-gaps
A15: 14 | B15: Feed Nutrients Management for Optimal Growth and Health in Contract Broiler Farming | C15: =CONCATENATE("Act as a founder of PoultryCare ERP as Cloud-based ERP solution specific to poultry industry, which serves for all poultry segments like layer, broiler, breeder, broiler integration, hatchery, feedmill and processing plant. As you have experience in both "&"technology and hand-holding exposer with poultry farm owners, use your journey of this into opportunity to address poultry farmer's business needs, pain points and problems through blogs. You play the role of Content marketing head to position PoultryCare"&" ERP using organic content marketing. You Are planning to run a blog for Feed Mill management and educate a poultry farmers, to resolving their", B15," give heading for run a blog for educating poultry farmers with their tone to create more engagement Write a title with SEO keywords to hook visitors to continue reading, description for google SEO,Blogs convert traffic into leads. Blogs go above and beyo"&"nd product descriptions. blog content around 1000 words with more detailed explanation having 4 to 6 sub-headings and 4 tags. give the 3 keywords, Don't mention PoltryCare ERP anywhere Content should be Farmel understanding tone to create more engagement "&"and analysis with google SEO.") -> Act as a founder of PoultryCare ERP as Cloud-based ERP solution specific to poultry industry, which serves for all poultry segments like layer, broiler, breeder, broiler integration, hatchery, feedmill and processing plant. As you have experience in both technology and hand-holding exposer with poultry farm owners, use your journey of this into opportunity to address poultry farmer's business needs, pain points and problems through blogs. You play the role of Content marketing head to position PoultryCare ERP using organic content marketing. You Are planning to run a blog for Feed Mill management and educate a poultry farmers, to resolving theirFeed Nutrients Management for Optimal Growth and Health in Contract Broiler Farming give heading for run a blog for educating poultry farmers with their tone to create more engagement Write a title with SEO keywords to hook visitors to continue reading, description for google SEO,Blogs convert traffic into leads. Blogs go above and beyond product descriptions. blog content around 1000 words with more detailed explanation having 4 to 6 sub-headings and 4 tags. give the 3 keywords, Don't mention PoltryCare ERP anywhere Content should be Farmel understanding tone to create more engagement and analysis with google SEO. | D15: 45566 | E15: Optimizing Feed Nutrients for Healthy and Rapid Growth in Contract Broiler Farming | F15: https://www.poultry.care/blog/optimizing-feed-nutrients-for-healthy-and-rapid-growth-in-contract-broiler-farming
A16: 15 | B16: How to Forecast Feed Needs in Contract Broiler Farming | C16: =CONCATENATE("Act as a founder of PoultryCare ERP as Cloud-based ERP solution specific to poultry industry, which serves for all poultry segments like layer, broiler, breeder, broiler integration, hatchery, feedmill and processing plant. As you have experience in both "&"technology and hand-holding exposer with poultry farm owners, use your journey of this into opportunity to address poultry farmer's business needs, pain points and problems through blogs. You play the role of Content marketing head to position PoultryCare"&" ERP using organic content marketing. You Are planning to run a blog for Feed Mill management and educate a poultry farmers, to resolving their", B16," give heading for run a blog for educating poultry farmers with their tone to create more engagement Write a title with SEO keywords to hook visitors to continue reading, description for google SEO,Blogs convert traffic into leads. Blogs go above and beyo"&"nd product descriptions. blog content around 1000 words with more detailed explanation having 4 to 6 sub-headings and 4 tags. give the 3 keywords, Don't mention PoltryCare ERP anywhere Content should be Farmel understanding tone to create more engagement "&"and analysis with google SEO.") -> Act as a founder of PoultryCare ERP as Cloud-based ERP solution specific to poultry industry, which serves for all poultry segments like layer, broiler, breeder, broiler integration, hatchery, feedmill and processing plant. As you have experience in both technology and hand-holding exposer with poultry farm owners, use your journey of this into opportunity to address poultry farmer's business needs, pain points and problems through blogs. You play the role of Content marketing head to position PoultryCare ERP using organic content marketing. You Are planning to run a blog for Feed Mill management and educate a poultry farmers, to resolving theirHow to Forecast Feed Needs in Contract Broiler Farming give heading for run a blog for educating poultry farmers with their tone to create more engagement Write a title with SEO keywords to hook visitors to continue reading, description for google SEO,Blogs convert traffic into leads. Blogs go above and beyond product descriptions. blog content around 1000 words with more detailed explanation having 4 to 6 sub-headings and 4 tags. give the 3 keywords, Don't mention PoltryCare ERP anywhere Content should be Farmel understanding tone to create more engagement and analysis with google SEO. | D16: 45568 | E16: Accurately Forecasting Feed Needs for Contract Broiler Farms to Maximize Profits | F16: https://www.poultry.care/blog/accurately-forecasting-feed-needs-for-contract-broiler-farms-to-maximize-profits
A17: 16 | B17: Creating and Following an Effective Medication Schedule in Contract Broiler Farming | C17: =CONCATENATE("Act as a founder of PoultryCare ERP as Cloud-based ERP solution specific to poultry industry, which serves for all poultry segments like layer, broiler, breeder, broiler integration, hatchery, feedmill and processing plant. As you have experience in both "&"technology and hand-holding exposer with poultry farm owners, use your journey of this into opportunity to address poultry farmer's business needs, pain points and problems through blogs. You play the role of Content marketing head to position PoultryCare"&" ERP using organic content marketing. You Are planning to run a blog for Feed Mill management and educate a poultry farmers, to resolving their", B17," give heading for run a blog for educating poultry farmers with their tone to create more engagement Write a title with SEO keywords to hook visitors to continue reading, description for google SEO,Blogs convert traffic into leads. Blogs go above and beyo"&"nd product descriptions. blog content around 1000 words with more detailed explanation having 4 to 6 sub-headings and 4 tags. give the 3 keywords, Don't mention PoltryCare ERP anywhere Content should be Farmel understanding tone to create more engagement "&"and analysis with google SEO.") -> Act as a founder of PoultryCare ERP as Cloud-based ERP solution specific to poultry industry, which serves for all poultry segments like layer, broiler, breeder, broiler integration, hatchery, feedmill and processing plant. As you have experience in both technology and hand-holding exposer with poultry farm owners, use your journey of this into opportunity to address poultry farmer's business needs, pain points and problems through blogs. You play the role of Content marketing head to position PoultryCare ERP using organic content marketing. You Are planning to run a blog for Feed Mill management and educate a poultry farmers, to resolving theirCreating and Following an Effective Medication Schedule in Contract Broiler Farming give heading for run a blog for educating poultry farmers with their tone to create more engagement Write a title with SEO keywords to hook visitors to continue reading, description for google SEO,Blogs convert traffic into leads. Blogs go above and beyond product descriptions. blog content around 1000 words with more detailed explanation having 4 to 6 sub-headings and 4 tags. give the 3 keywords, Don't mention PoltryCare ERP anywhere Content should be Farmel understanding tone to create more engagement and analysis with google SEO. | D17: 45570 | E17: How to Create and Follow an Effective Medication Schedule in Contract Broiler Farming | F17: https://www.poultry.care/blog/how-to-create-and-follow-an-effective-medication-schedule-in-contract-broiler-farming
A18: 17 | B18: Avoiding Data Manipulation in Contract Broiler Farming | C18: =CONCATENATE("Act as a founder of PoultryCare ERP as Cloud-based ERP solution specific to poultry industry, which serves for all poultry segments like layer, broiler, breeder, broiler integration, hatchery, feedmill and processing plant. As you have experience in both "&"technology and hand-holding exposer with poultry farm owners, use your journey of this into opportunity to address poultry farmer's business needs, pain points and problems through blogs. You play the role of Content marketing head to position PoultryCare"&" ERP using organic content marketing. You Are planning to run a blog for Feed Mill management and educate a poultry farmers, to resolving their", B18," give heading for run a blog for educating poultry farmers with their tone to create more engagement Write a title with SEO keywords to hook visitors to continue reading, description for google SEO,Blogs convert traffic into leads. Blogs go above and beyo"&"nd product descriptions. blog content around 1000 words with more detailed explanation having 4 to 6 sub-headings and 4 tags. give the 3 keywords, Don't mention PoltryCare ERP anywhere Content should be Farmel understanding tone to create more engagement "&"and analysis with google SEO.") -> Act as a founder of PoultryCare ERP as Cloud-based ERP solution specific to poultry industry, which serves for all poultry segments like layer, broiler, breeder, broiler integration, hatchery, feedmill and processing plant. As you have experience in both technology and hand-holding exposer with poultry farm owners, use your journey of this into opportunity to address poultry farmer's business needs, pain points and problems through blogs. You play the role of Content marketing head to position PoultryCare ERP using organic content marketing. You Are planning to run a blog for Feed Mill management and educate a poultry farmers, to resolving theirAvoiding Data Manipulation in Contract Broiler Farming give heading for run a blog for educating poultry farmers with their tone to create more engagement Write a title with SEO keywords to hook visitors to continue reading, description for google SEO,Blogs convert traffic into leads. Blogs go above and beyond product descriptions. blog content around 1000 words with more detailed explanation having 4 to 6 sub-headings and 4 tags. give the 3 keywords, Don't mention PoltryCare ERP anywhere Content should be Farmel understanding tone to create more engagement and analysis with google SEO. | D18: 45572 | E18: How to Prevent Data Manipulation in Contract Broiler Farming for Better Results | F18: https://www.poultry.care/blog/how-to-prevent-data-manipulation-in-contract-broiler-farming-for-better-results
